Workbook

Sheet All
A1: School | B1: Private? | C1: Board Division | D1: District | F1: Enrollment | G1: CCB | H1: CCG | I1: GOB | J1: GOG | K1: SOB | L1: TNG | M1: VBG | O1: Enrollment | P1: BKB | Q1: BKG | R1: CHC | S1: DAC | T1: SCB | U1: WR | W1: Enrollment | X1: BA | Y1: SBG | Z1: SOG | AA1: TNB | AB1: TRB | AC1: TRG | AD1: FF | AE1: FF
A2: Abingdon (A.-Avon) | B2: =IFERROR(VLOOKUP(A2,'Public v Private'!A:G,3,FALSE),"") -> 0 | C2: =IFERROR(VLOOKUP(A2,'Public v Private'!A:G,4,FALSE),"") -> 0 | D2: =IFERROR(VLOOKUP(A2,'Public v Private'!A:G,5,FALSE),"") -> 0 | F2: =IFERROR(INDEX(Fall!$1:$1048576,MATCH(All!$A2,Fall!$A:$A,FALSE),MATCH(All!F$1,Fall!$1:$1,FALSE)),"N/A") -> 270 | G2: =IFERROR(IF(INDEX(Fall!$1:$1048576,MATCH(All!$A2,Fall!$A:$A,FALSE),MATCH(All!G$1,Fall!$1:$1,FALSE))="","",INDEX(Fall!$1:$1048576,MATCH(All!$A2,Fall!$A:$A,FALSE),MATCH(All!G$1,Fall!$1:$1,FALSE))),"") -> 1A | H2: =IFERROR(IF(INDEX(Fall!$1:$1048576,MATCH(All!$A2,Fall!$A:$A,FALSE),MATCH(All!H$1,Fall!$1:$1,FALSE))="","",INDEX(Fall!$1:$1048576,MATCH(All!$A2,Fall!$A:$A,FALSE),MATCH(All!H$1,Fall!$1:$1,FALSE))),"") -> 1A | I2: =IFERROR(IF(INDEX(Fall!$1:$1048576,MATCH(All!$A2,Fall!$A:$A,FALSE),MATCH(All!I$1,Fall!$1:$1,FALSE))="","",INDEX(Fall!$1:$1048576,MATCH(All!$A2,Fall!$A:$A,FALSE),MATCH(All!I$1,Fall!$1:$1,FALSE))),"") -> 1A | J2: =IFERROR(IF(INDEX(Fall!$1:$1048576,MATCH(All!$A2,Fall!$A:$A,FALSE),MATCH(All!J$1,Fall!$1:$1,FALSE))="","",INDEX(Fall!$1:$1048576,MATCH(All!$A2,Fall!$A:$A,FALSE),MATCH(All!J$1,Fall!$1:$1,FALSE))),"") | K2: =IFERROR(IF(INDEX(Fall!$1:$1048576,MATCH(All!$A2,Fall!$A:$A,FALSE),MATCH(All!K$1,Fall!$1:$1,FALSE))="","",INDEX(Fall!$1:$1048576,MATCH(All!$A2,Fall!$A:$A,FALSE),MATCH(All!K$1,Fall!$1:$1,FALSE))),"") -> 1A | L2: =IFERROR(IF(INDEX(Fall!$1:$1048576,MATCH(All!$A2,Fall!$A:$A,FALSE),MATCH(All!L$1,Fall!$1:$1,FALSE))="","",INDEX(Fall!$1:$1048576,MATCH(All!$A2,Fall!$A:$A,FALSE),MATCH(All!L$1,Fall!$1:$1,FALSE))),"") | M2: =IFERROR(IF(INDEX(Fall!$1:$1048576,MATCH(All!$A2,Fall!$A:$A,FALSE),MATCH(All!M$1,Fall!$1:$1,FALSE))="","",INDEX(Fall!$1:$1048576,MATCH(All!$A2,Fall!$A:$A,FALSE),MATCH(All!M$1,Fall!$1:$1,FALSE))),"") -> 1A | O2: =IFERROR(IF(INDEX(Winter!$1:$1048576,MATCH(All!$A2,Winter!$A:$A,FALSE),MATCH(All!O$1,Winter!$1:$1,FALSE))="","",INDEX(Winter!$1:$1048576,MATCH(All!$A2,Winter!$A:$A,FALSE),MATCH(All!O$1,Winter!$1:$1,FALSE))),"") -> 270 | P2: =IFERROR(IF(INDEX(Winter!$1:$1048576,MATCH(All!$A2,Winter!$A:$A,FALSE),MATCH(All!P$1,Winter!$1:$1,FALSE))="","",INDEX(Winter!$1:$1048576,MATCH(All!$A2,Winter!$A:$A,FALSE),MATCH(All!P$1,Winter!$1:$1,FALSE))),"") -> 1A | Q2: =IFERROR(IF(INDEX(Winter!$1:$1048576,MATCH(All!$A2,Winter!$A:$A,FALSE),MATCH(All!Q$1,Winter!$1:$1,FALSE))="","",INDEX(Winter!$1:$1048576,MATCH(All!$A2,Winter!$A:$A,FALSE),MATCH(All!Q$1,Winter!$1:$1,FALSE))),"") -> 1A | R2: =IFERROR(IF(INDEX(Winter!$1:$1048576,MATCH(All!$A2,Winter!$A:$A,FALSE),MATCH(All!R$1,Winter!$1:$1,FALSE))="","",INDEX(Winter!$1:$1048576,MATCH(All!$A2,Winter!$A:$A,FALSE),MATCH(All!R$1,Winter!$1:$1,FALSE))),"") | S2: =IFERROR(IF(INDEX(Winter!$1:$1048576,MATCH(All!$A2,Winter!$A:$A,FALSE),MATCH(All!S$1,Winter!$1:$1,FALSE))="","",INDEX(Winter!$1:$1048576,MATCH(All!$A2,Winter!$A:$A,FALSE),MATCH(All!S$1,Winter!$1:$1,FALSE))),"") | T2: =IFERROR(IF(INDEX(Winter!$1:$1048576,MATCH(All!$A2,Winter!$A:$A,FALSE),MATCH(All!T$1,Winter!$1:$1,FALSE))="","",INDEX(Winter!$1:$1048576,MATCH(All!$A2,Winter!$A:$A,FALSE),MATCH(All!T$1,Winter!$1:$1,FALSE))),"") -> 1A | U2: =IFERROR(IF(INDEX(Winter!$1:$1048576,MATCH(All!$A2,Winter!$A:$A,FALSE),MATCH(All!U$1,Winter!$1:$1,FALSE))="","",INDEX(Winter!$1:$1048576,MATCH(All!$A2,Winter!$A:$A,FALSE),MATCH(All!U$1,Winter!$1:$1,FALSE))),"") -> 1A | W2: =IFERROR(IF(INDEX(Spring!$1:$1048576,MATCH(All!$A2,Spring!$A:$A,FALSE),MATCH(All!W$1,Spring!$1:$1,FALSE))="","",INDEX(Spring!$1:$1048576,MATCH(All!$A2,Spring!$A:$A,FALSE),MATCH(All!W$1,Spring!$1:$1,FALSE))),"") -> 270 | X2: =IFERROR(IF(INDEX(Spring!$1:$1048576,MATCH(All!$A2,Spring!$A:$A,FALSE),MATCH(All!X$1,Spring!$1:$1,FALSE))="","",INDEX(Spring!$1:$1048576,MATCH(All!$A2,Spring!$A:$A,FALSE),MATCH(All!X$1,Spring!$1:$1,FALSE))),"") -> 1A | Y2: =IFERROR(IF(INDEX(Spring!$1:$1048576,MATCH(All!$A2,Spring!$A:$A,FALSE),MATCH(All!Y$1,Spring!$1:$1,FALSE))="","",INDEX(Spring!$1:$1048576,MATCH(All!$A2,Spring!$A:$A,FALSE),MATCH(All!Y$1,Spring!$1:$1,FALSE))),"") -> 1A | Z2: =IFERROR(IF(INDEX(Spring!$1:$1048576,MATCH(All!$A2,Spring!$A:$A,FALSE),MATCH(All!Z$1,Spring!$1:$1,FALSE))="","",INDEX(Spring!$1:$1048576,MATCH(All!$A2,Spring!$A:$A,FALSE),MATCH(All!Z$1,Spring!$1:$1,FALSE))),"") | AA2: =IFERROR(IF(INDEX(Spring!$1:$1048576,MATCH(All!$A2,Spring!$A:$A,FALSE),MATCH(All!AA$1,Spring!$1:$1,FALSE))="","",INDEX(Spring!$1:$1048576,MATCH(All!$A2,Spring!$A:$A,FALSE),MATCH(All!AA$1,Spring!$1:$1,FALSE))),"") | AB2: =IFERROR(IF(INDEX(Spring!$1:$1048576,MATCH(All!$A2,Spring!$A:$A,FALSE),MATCH(All!AB$1,Spring!$1:$1,FALSE))="","",INDEX(Spring!$1:$1048576,MATCH(All!$A2,Spring!$A:$A,FALSE),MATCH(All!AB$1,Spring!$1:$1,FALSE))),"") -> 1A | AC2: =IFERROR(IF(INDEX(Spring!$1:$1048576,MATCH(All!$A2,Spring!$A:$A,FALSE),MATCH(All!AC$1,Spring!$1:$1,FALSE))="","",INDEX(Spring!$1:$1048576,MATCH(All!$A2,Spring!$A:$A,FALSE),MATCH(All!AC$1,Spring!$1:$1,FALSE))),"") -> 1A | AD2: =IFERROR(VLOOKUP(A2,'Flag Football'!A:A,1,FALSE),"") | AE2: =IF(AD2="","","1A")
A3: Addison (A. Trail) | B3: =IFERROR(VLOOKUP(A3,'Public v Private'!A:G,3,FALSE),"") -> 0 | C3: =IFERROR(VLOOKUP(A3,'Public v Private'!A:G,4,FALSE),"") -> 0 | D3: =IFERROR(VLOOKUP(A3,'Public v Private'!A:G,5,FALSE),"") -> 0 | F3: =IFERROR(INDEX(Fall!$1:$1048576,MATCH(All!$A3,Fall!$A:$A,FALSE),MATCH(All!F$1,Fall!$1:$1,FALSE)),"N/A") -> 1840 | G3: =IFERROR(IF(INDEX(Fall!$1:$1048576,MATCH(All!$A3,Fall!$A:$A,FALSE),MATCH(All!G$1,Fall!$1:$1,FALSE))="","",INDEX(Fall!$1:$1048576,MATCH(All!$A3,Fall!$A:$A,FALSE),MATCH(All!G$1,Fall!$1:$1,FALSE))),"") -> 3A | H3: =IFERROR(IF(INDEX(Fall!$1:$1048576,MATCH(All!$A3,Fall!$A:$A,FALSE),MATCH(All!H$1,Fall!$1:$1,FALSE))="","",INDEX(Fall!$1:$1048576,MATCH(All!$A3,Fall!$A:$A,FALSE),MATCH(All!H$1,Fall!$1:$1,FALSE))),"") -> 3A | I3: =IFERROR(IF(INDEX(Fall!$1:$1048576,MATCH(All!$A3,Fall!$A:$A,FALSE),MATCH(All!I$1,Fall!$1:$1,FALSE))="","",INDEX(Fall!$1:$1048576,MATCH(All!$A3,Fall!$A:$A,FALSE),MATCH(All!I$1,Fall!$1:$1,FALSE))),"") -> 3A | J3: =IFERROR(IF(INDEX(Fall!$1:$1048576,MATCH(All!$A3,Fall!$A:$A,FALSE),MATCH(All!J$1,Fall!$1:$1,FALSE))="","",INDEX(Fall!$1:$1048576,MATCH(All!$A3,Fall!$A:$A,FALSE),MATCH(All!J$1,Fall!$1:$1,FALSE))),"") -> 2A | K3: =IFERROR(IF(INDEX(Fall!$1:$1048576,MATCH(All!$A3,Fall!$A:$A,FALSE),MATCH(All!K$1,Fall!$1:$1,FALSE))="","",INDEX(Fall!$1:$1048576,MATCH(All!$A3,Fall!$A:$A,FALSE),MATCH(All!K$1,Fall!$1:$1,FALSE))),"") -> 3A | L3: =IFERROR(IF(INDEX(Fall!$1:$1048576,MATCH(All!$A3,Fall!$A:$A,FALSE),MATCH(All!L$1,Fall!$1:$1,FALSE))="","",INDEX(Fall!$1:$1048576,MATCH(All!$A3,Fall!$A:$A,FALSE),MATCH(All!L$1,Fall!$1:$1,FALSE))),"") -> 2A | M3: =IFERROR(IF(INDEX(Fall!$1:$1048576,MATCH(All!$A3,Fall!$A:$A,FALSE),MATCH(All!M$1,Fall!$1:$1,FALSE))="","",INDEX(Fall!$1:$1048576,MATCH(All!$A3,Fall!$A:$A,FALSE),MATCH(All!M$1,Fall!$1:$1,FALSE))),"") -> 4A | O3: =IFERROR(IF(INDEX(Winter!$1:$1048576,MATCH(All!$A3,Winter!$A:$A,FALSE),MATCH(All!O$1,Winter!$1:$1,FALSE))="","",INDEX(Winter!$1:$1048576,MATCH(All!$A3,Winter!$A:$A,FALSE),MATCH(All!O$1,Winter!$1:$1,FALSE))),"") -> 1840 | P3: =IFERROR(IF(INDEX(Winter!$1:$1048576,MATCH(All!$A3,Winter!$A:$A,FALSE),MATCH(All!P$1,Winter!$1:$1,FALSE))="","",INDEX(Winter!$1:$1048576,MATCH(All!$A3,Winter!$A:$A,FALSE),MATCH(All!P$1,Winter!$1:$1,FALSE))),"") -> 4A | Q3: =IFERROR(IF(INDEX(Winter!$1:$1048576,MATCH(All!$A3,Winter!$A:$A,FALSE),MATCH(All!Q$1,Winter!$1:$1,FALSE))="","",INDEX(Winter!$1:$1048576,MATCH(All!$A3,Winter!$A:$A,FALSE),MATCH(All!Q$1,Winter!$1:$1,FALSE))),"") -> 4A | R3: =IFERROR(IF(INDEX(Winter!$1:$1048576,MATCH(All!$A3,Winter!$A:$A,FALSE),MATCH(All!R$1,Winter!$1:$1,FALSE))="","",INDEX(Winter!$1:$1048576,MATCH(All!$A3,Winter!$A:$A,FALSE),MATCH(All!R$1,Winter!$1:$1,FALSE))),"") -> C | S3: =IFERROR(IF(INDEX(Winter!$1:$1048576,MATCH(All!$A3,Winter!$A:$A,FALSE),MATCH(All!S$1,Winter!$1:$1,FALSE))="","",INDEX(Winter!$1:$1048576,MATCH(All!$A3,Winter!$A:$A,FALSE),MATCH(All!S$1,Winter!$1:$1,FALSE))),"") -> 2A | T3: =IFERROR(IF(INDEX(Winter!$1:$1048576,MATCH(All!$A3,Winter!$A:$A,FALSE),MATCH(All!T$1,Winter!$1:$1,FALSE))="","",INDEX(Winter!$1:$1048576,MATCH(All!$A3,Winter!$A:$A,FALSE),MATCH(All!T$1,Winter!$1:$1,FALSE))),"") -> 2A | U3: =IFERROR(IF(INDEX(Winter!$1:$1048576,MATCH(All!$A3,Winter!$A:$A,FALSE),MATCH(All!U$1,Winter!$1:$1,FALSE))="","",INDEX(Winter!$1:$1048576,MATCH(All!$A3,Winter!$A:$A,FALSE),MATCH(All!U$1,Winter!$1:$1,FALSE))),"") -> 3A | W3: =IFERROR(IF(INDEX(Spring!$1:$1048576,MATCH(All!$A3,Spring!$A:$A,FALSE),MATCH(All!W$1,Spring!$1:$1,FALSE))="","",INDEX(Spring!$1:$1048576,MATCH(All!$A3,Spring!$A:$A,FALSE),MATCH(All!W$1,Spring!$1:$1,FALSE))),"") -> 1840 | X3: =IFERROR(IF(INDEX(Spring!$1:$1048576,MATCH(All!$A3,Spring!$A:$A,FALSE),MATCH(All!X$1,Spring!$1:$1,FALSE))="","",INDEX(Spring!$1:$1048576,MATCH(All!$A3,Spring!$A:$A,FALSE),MATCH(All!X$1,Spring!$1:$1,FALSE))),"") -> 4A | Y3: =IFERROR(IF(INDEX(Spring!$1:$1048576,MATCH(All!$A3,Spring!$A:$A,FALSE),MATCH(All!Y$1,Spring!$1:$1,FALSE))="","",INDEX(Spring!$1:$1048576,MATCH(All!$A3,Spring!$A:$A,FALSE),MATCH(All!Y$1,Spring!$1:$1,FALSE))),"") -> 4A | Z3: =IFERROR(IF(INDEX(Spring!$1:$1048576,MATCH(All!$A3,Spring!$A:$A,FALSE),MATCH(All!Z$1,Spring!$1:$1,FALSE))="","",INDEX(Spring!$1:$1048576,MATCH(All!$A3,Spring!$A:$A,FALSE),MATCH(All!Z$1,Spring!$1:$1,FALSE))),"") -> 3A | AA3: =IFERROR(IF(INDEX(Spring!$1:$1048576,MATCH(All!$A3,Spring!$A:$A,FALSE),MATCH(All!AA$1,Spring!$1:$1,FALSE))="","",INDEX(Spring!$1:$1048576,MATCH(All!$A3,Spring!$A:$A,FALSE),MATCH(All!AA$1,Spring!$1:$1,FALSE))),"") -> 2A | AB3: =IFERROR(IF(INDEX(Spring!$1:$1048576,MATCH(All!$A3,Spring!$A:$A,FALSE),MATCH(All!AB$1,Spring!$1:$1,FALSE))="","",INDEX(Spring!$1:$1048576,MATCH(All!$A3,Spring!$A:$A,FALSE),MATCH(All!AB$1,Spring!$1:$1,FALSE))),"") -> 3A | AC3: =IFERROR(IF(INDEX(Spring!$1:$1048576,MATCH(All!$A3,Spring!$A:$A,FALSE),MATCH(All!AC$1,Spring!$1:$1,FALSE))="","",INDEX(Spring!$1:$1048576,MATCH(All!$A3,Spring!$A:$A,FALSE),MATCH(All!AC$1,Spring!$1:$1,FALSE))),"") -> 3A | AD3: =IFERROR(VLOOKUP(A3,'Flag Football'!A:A,1,FALSE),"") -> Addison (A. Trail) | AE3: =IF(AD3="","","1A") -> 1A
A4: Albion (Edwards County) | B4: =IFERROR(VLOOKUP(A4,'Public v Private'!A:G,3,FALSE),"") -> 0 | C4: =IFERROR(VLOOKUP(A4,'Public v Private'!A:G,4,FALSE),"") -> 0 | D4: =IFERROR(VLOOKUP(A4,'Public v Private'!A:G,5,FALSE),"") -> 0 | F4: =IFERROR(INDEX(Fall!$1:$1048576,MATCH(All!$A4,Fall!$A:$A,FALSE),MATCH(All!F$1,Fall!$1:$1,FALSE)),"N/A") -> 215 | G4: =IFERROR(IF(INDEX(Fall!$1:$1048576,MATCH(All!$A4,Fall!$A:$A,FALSE),MATCH(All!G$1,Fall!$1:$1,FALSE))="","",INDEX(Fall!$1:$1048576,MATCH(All!$A4,Fall!$A:$A,FALSE),MATCH(All!G$1,Fall!$1:$1,FALSE))),"") | H4: =IFERROR(IF(INDEX(Fall!$1:$1048576,MATCH(All!$A4,Fall!$A:$A,FALSE),MATCH(All!H$1,Fall!$1:$1,FALSE))="","",INDEX(Fall!$1:$1048576,MATCH(All!$A4,Fall!$A:$A,FALSE),MATCH(All!H$1,Fall!$1:$1,FALSE))),"") | I4: =IFERROR(IF(INDEX(Fall!$1:$1048576,MATCH(All!$A4,Fall!$A:$A,FALSE),MATCH(All!I$1,Fall!$1:$1,FALSE))="","",INDEX(Fall!$1:$1048576,MATCH(All!$A4,Fall!$A:$A,FALSE),MATCH(All!I$1,Fall!$1:$1,FALSE))),"") -> 1A | J4: =IFERROR(IF(INDEX(Fall!$1:$1048576,MATCH(All!$A4,Fall!$A:$A,FALSE),MATCH(All!J$1,Fall!$1:$1,FALSE))="","",INDEX(Fall!$1:$1048576,MATCH(All!$A4,Fall!$A:$A,FALSE),MATCH(All!J$1,Fall!$1:$1,FALSE))),"") -> 1A | K4: =IFERROR(IF(INDEX(Fall!$1:$1048576,MATCH(All!$A4,Fall!$A:$A,FALSE),MATCH(All!K$1,Fall!$1:$1,FALSE))="","",INDEX(Fall!$1:$1048576,MATCH(All!$A4,Fall!$A:$A,FALSE),MATCH(All!K$1,Fall!$1:$1,FALSE))),"") | L4: =IFERROR(IF(INDEX(Fall!$1:$1048576,MATCH(All!$A4,Fall!$A:$A,FALSE),MATCH(All!L$1,Fall!$1:$1,FALSE))="","",INDEX(Fall!$1:$1048576,MATCH(All!$A4,Fall!$A:$A,FALSE),MATCH(All!L$1,Fall!$1:$1,FALSE))),"") | M4: =IFERROR(IF(INDEX(Fall!$1:$1048576,MATCH(All!$A4,Fall!$A:$A,FALSE),MATCH(All!M$1,Fall!$1:$1,FALSE))="","",INDEX(Fall!$1:$1048576,MATCH(All!$A4,Fall!$A:$A,FALSE),MATCH(All!M$1,Fall!$1:$1,FALSE))),"") -> 1A | O4: =IFERROR(IF(INDEX(Winter!$1:$1048576,MATCH(All!$A4,Winter!$A:$A,FALSE),MATCH(All!O$1,Winter!$1:$1,FALSE))="","",INDEX(Winter!$1:$1048576,MATCH(All!$A4,Winter!$A:$A,FALSE),MATCH(All!O$1,Winter!$1:$1,FALSE))),"") -> 215 | P4: =IFERROR(IF(INDEX(Winter!$1:$1048576,MATCH(All!$A4,Winter!$A:$A,FALSE),MATCH(All!P$1,Winter!$1:$1,FALSE))="","",INDEX(Winter!$1:$1048576,MATCH(All!$A4,Winter!$A:$A,FALSE),MATCH(All!P$1,Winter!$1:$1,FALSE))),"") -> 1A | Q4: =IFERROR(IF(INDEX(Winter!$1:$1048576,MATCH(All!$A4,Winter!$A:$A,FALSE),MATCH(All!Q$1,Winter!$1:$1,FALSE))="","",INDEX(Winter!$1:$1048576,MATCH(All!$A4,Winter!$A:$A,FALSE),MATCH(All!Q$1,Winter!$1:$1,FALSE))),"") -> 1A | R4: =IFERROR(IF(INDEX(Winter!$1:$1048576,MATCH(All!$A4,Winter!$A:$A,FALSE),MATCH(All!R$1,Winter!$1:$1,FALSE))="","",INDEX(Winter!$1:$1048576,MATCH(All!$A4,Winter!$A:$A,FALSE),MATCH(All!R$1,Winter!$1:$1,FALSE))),"") | S4: =IFERROR(IF(INDEX(Winter!$1:$1048576,MATCH(All!$A4,Winter!$A:$A,FALSE),MATCH(All!S$1,Winter!$1:$1,FALSE))="","",INDEX(Winter!$1:$1048576,MATCH(All!$A4,Winter!$A:$A,FALSE),MATCH(All!S$1,Winter!$1:$1,FALSE))),"") | T4: =IFERROR(IF(INDEX(Winter!$1:$1048576,MATCH(All!$A4,Winter!$A:$A,FALSE),MATCH(All!T$1,Winter!$1:$1,FALSE))="","",INDEX(Winter!$1:$1048576,MATCH(All!$A4,Winter!$A:$A,FALSE),MATCH(All!T$1,Winter!$1:$1,FALSE))),"") -> 1A | U4: =IFERROR(IF(INDEX(Winter!$1:$1048576,MATCH(All!$A4,Winter!$A:$A,FALSE),MATCH(All!U$1,Winter!$1:$1,FALSE))="","",INDEX(Winter!$1:$1048576,MATCH(All!$A4,Winter!$A:$A,FALSE),MATCH(All!U$1,Winter!$1:$1,FALSE))),"") | W4: =IFERROR(IF(INDEX(Spring!$1:$1048576,MATCH(All!$A4,Spring!$A:$A,FALSE),MATCH(All!W$1,Spring!$1:$1,FALSE))="","",INDEX(Spring!$1:$1048576,MATCH(All!$A4,Spring!$A:$A,FALSE),MATCH(All!W$1,Spring!$1:$1,FALSE))),"") -> 215 | X4: =IFERROR(IF(INDEX(Spring!$1:$1048576,MATCH(All!$A4,Spring!$A:$A,FALSE),MATCH(All!X$1,Spring!$1:$1,FALSE))="","",INDEX(Spring!$1:$1048576,MATCH(All!$A4,Spring!$A:$A,FALSE),MATCH(All!X$1,Spring!$1:$1,FALSE))),"") -> 1A | Y4: =IFERROR(IF(INDEX(Spring!$1:$1048576,MATCH(All!$A4,Spring!$A:$A,FALSE),MATCH(All!Y$1,Spring!$1:$1,FALSE))="","",INDEX(Spring!$1:$1048576,MATCH(All!$A4,Spring!$A:$A,FALSE),MATCH(All!Y$1,Spring!$1:$1,FALSE))),"") -> 1A | Z4: =IFERROR(IF(INDEX(Spring!$1:$1048576,MATCH(All!$A4,Spring!$A:$A,FALSE),MATCH(All!Z$1,Spring!$1:$1,FALSE))="","",INDEX(Spring!$1:$1048576,MATCH(All!$A4,Spring!$A:$A,FALSE),MATCH(All!Z$1,Spring!$1:$1,FALSE))),"") | AA4: =IFERROR(IF(INDEX(Spring!$1:$1048576,MATCH(All!$A4,Spring!$A:$A,FALSE),MATCH(All!AA$1,Spring!$1:$1,FALSE))="","",INDEX(Spring!$1:$1048576,MATCH(All!$A4,Spring!$A:$A,FALSE),MATCH(All!AA$1,Spring!$1:$1,FALSE))),"") | AB4: =IFERROR(IF(INDEX(Spring!$1:$1048576,MATCH(All!$A4,Spring!$A:$A,FALSE),MATCH(All!AB$1,Spring!$1:$1,FALSE))="","",INDEX(Spring!$1:$1048576,MATCH(All!$A4,Spring!$A:$A,FALSE),MATCH(All!AB$1,Spring!$1:$1,FALSE))),"") | AC4: =IFERROR(IF(INDEX(Spring!$1:$1048576,MATCH(All!$A4,Spring!$A:$A,FALSE),MATCH(All!AC$1,Spring!$1:$1,FALSE))="","",INDEX(Spring!$1:$1048576,MATCH(All!$A4,Spring!$A:$A,FALSE),MATCH(All!AC$1,Spring!$1:$1,FALSE))),"") | AD4: =IFERROR(VLOOKUP(A4,'Flag Football'!A:A,1,FALSE),"") | AE4: =IF(AD4="","","1A")
A5: Aledo (Mercer County) | B5: =IFERROR(VLOOKUP(A5,'Public v Private'!A:G,3,FALSE),"") -> 0 | C5: =IFERROR(VLOOKUP(A5,'Public v Private'!A:G,4,FALSE),"") -> 0 | D5: =IFERROR(VLOOKUP(A5,'Public v Private'!A:G,5,FALSE),"") -> 0 | F5: =IFERROR(INDEX(Fall!$1:$1048576,MATCH(All!$A5,Fall!$A:$A,FALSE),MATCH(All!F$1,Fall!$1:$1,FALSE)),"N/A") -> 399 | G5: =IFERROR(IF(INDEX(Fall!$1:$1048576,MATCH(All!$A5,Fall!$A:$A,FALSE),MATCH(All!G$1,Fall!$1:$1,FALSE))="","",INDEX(Fall!$1:$1048576,MATCH(All!$A5,Fall!$A:$A,FALSE),MATCH(All!G$1,Fall!$1:$1,FALSE))),"") -> 1A | H5: =IFERROR(IF(INDEX(Fall!$1:$1048576,MATCH(All!$A5,Fall!$A:$A,FALSE),MATCH(All!H$1,Fall!$1:$1,FALSE))="","",INDEX(Fall!$1:$1048576,MATCH(All!$A5,Fall!$A:$A,FALSE),MATCH(All!H$1,Fall!$1:$1,FALSE))),"") -> 1A | I5: =IFERROR(IF(INDEX(Fall!$1:$1048576,MATCH(All!$A5,Fall!$A:$A,FALSE),MATCH(All!I$1,Fall!$1:$1,FALSE))="","",INDEX(Fall!$1:$1048576,MATCH(All!$A5,Fall!$A:$A,FALSE),MATCH(All!I$1,Fall!$1:$1,FALSE))),"") -> 1A | J5: =IFERROR(IF(INDEX(Fall!$1:$1048576,MATCH(All!$A5,Fall!$A:$A,FALSE),MATCH(All!J$1,Fall!$1:$1,FALSE))="","",INDEX(Fall!$1:$1048576,MATCH(All!$A5,Fall!$A:$A,FALSE),MATCH(All!J$1,Fall!$1:$1,FALSE))),"") -> 1A | K5: =IFERROR(IF(INDEX(Fall!$1:$1048576,MATCH(All!$A5,Fall!$A:$A,FALSE),MATCH(All!K$1,Fall!$1:$1,FALSE))="","",INDEX(Fall!$1:$1048576,MATCH(All!$A5,Fall!$A:$A,FALSE),MATCH(All!K$1,Fall!$1:$1,FALSE))),"") | L5: =IFERROR(IF(INDEX(Fall!$1:$1048576,MATCH(All!$A5,Fall!$A:$A,FALSE),MATCH(All!L$1,Fall!$1:$1,FALSE))="","",INDEX(Fall!$1:$1048576,MATCH(All!$A5,Fall!$A:$A,FALSE),MATCH(All!L$1,Fall!$1:$1,FALSE))),"") | M5: =IFERROR(IF(INDEX(Fall!$1:$1048576,MATCH(All!$A5,Fall!$A:$A,FALSE),MATCH(All!M$1,Fall!$1:$1,FALSE))="","",INDEX(Fall!$1:$1048576,MATCH(All!$A5,Fall!$A:$A,FALSE),MATCH(All!M$1,Fall!$1:$1,FALSE))),"") -> 2A | O5: =IFERROR(IF(INDEX(Winter!$1:$1048576,MATCH(All!$A5,Winter!$A:$A,FALSE),MATCH(All!O$1,Winter!$1:$1,FALSE))="","",INDEX(Winter!$1:$1048576,MATCH(All!$A5,Winter!$A:$A,FALSE),MATCH(All!O$1,Winter!$1:$1,FALSE))),"") -> 399 | P5: =IFERROR(IF(INDEX(Winter!$1:$1048576,MATCH(All!$A5,Winter!$A:$A,FALSE),MATCH(All!P$1,Winter!$1:$1,FALSE))="","",INDEX(Winter!$1:$1048576,MATCH(All!$A5,Winter!$A:$A,FALSE),MATCH(All!P$1,Winter!$1:$1,FALSE))),"") -> 2A | Q5: =IFERROR(IF(INDEX(Winter!$1:$1048576,MATCH(All!$A5,Winter!$A:$A,FALSE),MATCH(All!Q$1,Winter!$1:$1,FALSE))="","",INDEX(Winter!$1:$1048576,MATCH(All!$A5,Winter!$A:$A,FALSE),MATCH(All!Q$1,Winter!$1:$1,FALSE))),"") -> 2A | R5: =IFERROR(IF(INDEX(Winter!$1:$1048576,MATCH(All!$A5,Winter!$A:$A,FALSE),MATCH(All!R$1,Winter!$1:$1,FALSE))="","",INDEX(Winter!$1:$1048576,MATCH(All!$A5,Winter!$A:$A,FALSE),MATCH(All!R$1,Winter!$1:$1,FALSE))),"") | S5: =IFERROR(IF(INDEX(Winter!$1:$1048576,MATCH(All!$A5,Winter!$A:$A,FALSE),MATCH(All!S$1,Winter!$1:$1,FALSE))="","",INDEX(Winter!$1:$1048576,MATCH(All!$A5,Winter!$A:$A,FALSE),MATCH(All!S$1,Winter!$1:$1,FALSE))),"") | T5: =IFERROR(IF(INDEX(Winter!$1:$1048576,MATCH(All!$A5,Winter!$A:$A,FALSE),MATCH(All!T$1,Winter!$1:$1,FALSE))="","",INDEX(Winter!$1:$1048576,MATCH(All!$A5,Winter!$A:$A,FALSE),MATCH(All!T$1,Winter!$1:$1,FALSE))),"") -> 1A | U5: =IFERROR(IF(INDEX(Winter!$1:$1048576,MATCH(All!$A5,Winter!$A:$A,FALSE),MATCH(All!U$1,Winter!$1:$1,FALSE))="","",INDEX(Winter!$1:$1048576,MATCH(All!$A5,Winter!$A:$A,FALSE),MATCH(All!U$1,Winter!$1:$1,FALSE))),"") -> 1A | W5: =IFERROR(IF(INDEX(Spring!$1:$1048576,MATCH(All!$A5,Spring!$A:$A,FALSE),MATCH(All!W$1,Spring!$1:$1,FALSE))="","",INDEX(Spring!$1:$1048576,MATCH(All!$A5,Spring!$A:$A,FALSE),MATCH(All!W$1,Spring!$1:$1,FALSE))),"") -> 399 | X5: =IFERROR(IF(INDEX(Spring!$1:$1048576,MATCH(All!$A5,Spring!$A:$A,FALSE),MATCH(All!X$1,Spring!$1:$1,FALSE))="","",INDEX(Spring!$1:$1048576,MATCH(All!$A5,Spring!$A:$A,FALSE),MATCH(All!X$1,Spring!$1:$1,FALSE))),"") -> 2A | Y5: =IFERROR(IF(INDEX(Spring!$1:$1048576,MATCH(All!$A5,Spring!$A:$A,FALSE),MATCH(All!Y$1,Spring!$1:$1,FALSE))="","",INDEX(Spring!$1:$1048576,MATCH(All!$A5,Spring!$A:$A,FALSE),MATCH(All!Y$1,Spring!$1:$1,FALSE))),"") -> 2A | Z5: =IFERROR(IF(INDEX(Spring!$1:$1048576,MATCH(All!$A5,Spring!$A:$A,FALSE),MATCH(All!Z$1,Spring!$1:$1,FALSE))="","",INDEX(Spring!$1:$1048576,MATCH(All!$A5,Spring!$A:$A,FALSE),MATCH(All!Z$1,Spring!$1:$1,FALSE))),"") | AA5: =IFERROR(IF(INDEX(Spring!$1:$1048576,MATCH(All!$A5,Spring!$A:$A,FALSE),MATCH(All!AA$1,Spring!$1:$1,FALSE))="","",INDEX(Spring!$1:$1048576,MATCH(All!$A5,Spring!$A:$A,FALSE),MATCH(All!AA$1,Spring!$1:$1,FALSE))),"") | AB5: =IFERROR(IF(INDEX(Spring!$1:$1048576,MATCH(All!$A5,Spring!$A:$A,FALSE),MATCH(All!AB$1,Spring!$1:$1,FALSE))="","",INDEX(Spring!$1:$1048576,MATCH(All!$A5,Spring!$A:$A,FALSE),MATCH(All!AB$1,Spring!$1:$1,FALSE))),"") -> 1A | AC5: =IFERROR(IF(INDEX(Spring!$1:$1048576,MATCH(All!$A5,Spring!$A:$A,FALSE),MATCH(All!AC$1,Spring!$1:$1,FALSE))="","",INDEX(Spring!$1:$1048576,MATCH(All!$A5,Spring!$A:$A,FALSE),MATCH(All!AC$1,Spring!$1:$1,FALSE))),"") -> 1A | AD5: =IFERROR(VLOOKUP(A5,'Flag Football'!A:A,1,FALSE),"") | AE5: =IF(AD5="","","1A")
A6: Algonquin (Jacobs) | B6: =IFERROR(VLOOKUP(A6,'Public v Private'!A:G,3,FALSE),"") -> 0 | C6: =IFERROR(VLOOKUP(A6,'Public v Private'!A:G,4,FALSE),"") -> 0 | D6: =IFERROR(VLOOKUP(A6,'Public v Private'!A:G,5,FALSE),"") -> 0 | F6: =IFERROR(INDEX(Fall!$1:$1048576,MATCH(All!$A6,Fall!$A:$A,FALSE),MATCH(All!F$1,Fall!$1:$1,FALSE)),"N/A") -> 2048 | G6: =IFERROR(IF(INDEX(Fall!$1:$1048576,MATCH(All!$A6,Fall!$A:$A,FALSE),MATCH(All!G$1,Fall!$1:$1,FALSE))="","",INDEX(Fall!$1:$1048576,MATCH(All!$A6,Fall!$A:$A,FALSE),MATCH(All!G$1,Fall!$1:$1,FALSE))),"") -> 3A | H6: =IFERROR(IF(INDEX(Fall!$1:$1048576,MATCH(All!$A6,Fall!$A:$A,FALSE),MATCH(All!H$1,Fall!$1:$1,FALSE))="","",INDEX(Fall!$1:$1048576,MATCH(All!$A6,Fall!$A:$A,FALSE),MATCH(All!H$1,Fall!$1:$1,FALSE))),"") -> 3A | I6: =IFERROR(IF(INDEX(Fall!$1:$1048576,MATCH(All!$A6,Fall!$A:$A,FALSE),MATCH(All!I$1,Fall!$1:$1,FALSE))="","",INDEX(Fall!$1:$1048576,MATCH(All!$A6,Fall!$A:$A,FALSE),MATCH(All!I$1,Fall!$1:$1,FALSE))),"") -> 3A | J6: =IFERROR(IF(INDEX(Fall!$1:$1048576,MATCH(All!$A6,Fall!$A:$A,FALSE),MATCH(All!J$1,Fall!$1:$1,FALSE))="","",INDEX(Fall!$1:$1048576,MATCH(All!$A6,Fall!$A:$A,FALSE),MATCH(All!J$1,Fall!$1:$1,FALSE))),"") -> 2A | K6: =IFERROR(IF(INDEX(Fall!$1:$1048576,MATCH(All!$A6,Fall!$A:$A,FALSE),MATCH(All!K$1,Fall!$1:$1,FALSE))="","",INDEX(Fall!$1:$1048576,MATCH(All!$A6,Fall!$A:$A,FALSE),MATCH(All!K$1,Fall!$1:$1,FALSE))),"") -> 3A | L6: =IFERROR(IF(INDEX(Fall!$1:$1048576,MATCH(All!$A6,Fall!$A:$A,FALSE),MATCH(All!L$1,Fall!$1:$1,FALSE))="","",INDEX(Fall!$1:$1048576,MATCH(All!$A6,Fall!$A:$A,FALSE),MATCH(All!L$1,Fall!$1:$1,FALSE))),"") -> 2A | M6: =IFERROR(IF(INDEX(Fall!$1:$1048576,MATCH(All!$A6,Fall!$A:$A,FALSE),MATCH(All!M$1,Fall!$1:$1,FALSE))="","",INDEX(Fall!$1:$1048576,MATCH(All!$A6,Fall!$A:$A,FALSE),MATCH(All!M$1,Fall!$1:$1,FALSE))),"") -> 4A | O6: =IFERROR(IF(INDEX(Winter!$1:$1048576,MATCH(All!$A6,Winter!$A:$A,FALSE),MATCH(All!O$1,Winter!$1:$1,FALSE))="","",INDEX(Winter!$1:$1048576,MATCH(All!$A6,Winter!$A:$A,FALSE),MATCH(All!O$1,Winter!$1:$1,FALSE))),"") -> 2048 | P6: =IFERROR(IF(INDEX(Winter!$1:$1048576,MATCH(All!$A6,Winter!$A:$A,FALSE),MATCH(All!P$1,Winter!$1:$1,FALSE))="","",INDEX(Winter!$1:$1048576,MATCH(All!$A6,Winter!$A:$A,FALSE),MATCH(All!P$1,Winter!$1:$1,FALSE))),"") -> 4A | Q6: =IFERROR(IF(INDEX(Winter!$1:$1048576,MATCH(All!$A6,Winter!$A:$A,FALSE),MATCH(All!Q$1,Winter!$1:$1,FALSE))="","",INDEX(Winter!$1:$1048576,MATCH(All!$A6,Winter!$A:$A,FALSE),MATCH(All!Q$1,Winter!$1:$1,FALSE))),"") -> 4A | R6: =IFERROR(IF(INDEX(Winter!$1:$1048576,MATCH(All!$A6,Winter!$A:$A,FALSE),MATCH(All!R$1,Winter!$1:$1,FALSE))="","",INDEX(Winter!$1:$1048576,MATCH(All!$A6,Winter!$A:$A,FALSE),MATCH(All!R$1,Winter!$1:$1,FALSE))),"") -> 3A | S6: =IFERROR(IF(INDEX(Winter!$1:$1048576,MATCH(All!$A6,Winter!$A:$A,FALSE),MATCH(All!S$1,Winter!$1:$1,FALSE))="","",INDEX(Winter!$1:$1048576,MATCH(All!$A6,Winter!$A:$A,FALSE),MATCH(All!S$1,Winter!$1:$1,FALSE))),"") -> 3A | T6: =IFERROR(IF(INDEX(Winter!$1:$1048576,MATCH(All!$A6,Winter!$A:$A,FALSE),MATCH(All!T$1,Winter!$1:$1,FALSE))="","",INDEX(Winter!$1:$1048576,MATCH(All!$A6,Winter!$A:$A,FALSE),MATCH(All!T$1,Winter!$1:$1,FALSE))),"") -> 2A | U6: =IFERROR(IF(INDEX(Winter!$1:$1048576,MATCH(All!$A6,Winter!$A:$A,FALSE),MATCH(All!U$1,Winter!$1:$1,FALSE))="","",INDEX(Winter!$1:$1048576,MATCH(All!$A6,Winter!$A:$A,FALSE),MATCH(All!U$1,Winter!$1:$1,FALSE))),"") -> 3A | W6: =IFERROR(IF(INDEX(Spring!$1:$1048576,MATCH(All!$A6,Spring!$A:$A,FALSE),MATCH(All!W$1,Spring!$1:$1,FALSE))="","",INDEX(Spring!$1:$1048576,MATCH(All!$A6,Spring!$A:$A,FALSE),MATCH(All!W$1,Spring!$1:$1,FALSE))),"") -> 2048 | X6: =IFERROR(IF(INDEX(Spring!$1:$1048576,MATCH(All!$A6,Spring!$A:$A,FALSE),MATCH(All!X$1,Spring!$1:$1,FALSE))="","",INDEX(Spring!$1:$1048576,MATCH(All!$A6,Spring!$A:$A,FALSE),MATCH(All!X$1,Spring!$1:$1,FALSE))),"") -> 4A | Y6: =IFERROR(IF(INDEX(Spring!$1:$1048576,MATCH(All!$A6,Spring!$A:$A,FALSE),MATCH(All!Y$1,Spring!$1:$1,FALSE))="","",INDEX(Spring!$1:$1048576,MATCH(All!$A6,Spring!$A:$A,FALSE),MATCH(All!Y$1,Spring!$1:$1,FALSE))),"") -> 4A | Z6: =IFERROR(IF(INDEX(Spring!$1:$1048576,MATCH(All!$A6,Spring!$A:$A,FALSE),MATCH(All!Z$1,Spring!$1:$1,FALSE))="","",INDEX(Spring!$1:$1048576,MATCH(All!$A6,Spring!$A:$A,FALSE),MATCH(All!Z$1,Spring!$1:$1,FALSE))),"") -> 3A | AA6: =IFERROR(IF(INDEX(Spring!$1:$1048576,MATCH(All!$A6,Spring!$A:$A,FALSE),MATCH(All!AA$1,Spring!$1:$1,FALSE))="","",INDEX(Spring!$1:$1048576,MATCH(All!$A6,Spring!$A:$A,FALSE),MATCH(All!AA$1,Spring!$1:$1,FALSE))),"") -> 2A | AB6: =IFERROR(IF(INDEX(Spring!$1:$1048576,MATCH(All!$A6,Spring!$A:$A,FALSE),MATCH(All!AB$1,Spring!$1:$1,FALSE))="","",INDEX(Spring!$1:$1048576,MATCH(All!$A6,Spring!$A:$A,FALSE),MATCH(All!AB$1,Spring!$1:$1,FALSE))),"") -> 3A | AC6: =IFERROR(IF(INDEX(Spring!$1:$1048576,MATCH(All!$A6,Spring!$A:$A,FALSE),MATCH(All!AC$1,Spring!$1:$1,FALSE))="","",INDEX(Spring!$1:$1048576,MATCH(All!$A6,Spring!$A:$A,FALSE),MATCH(All!AC$1,Spring!$1:$1,FALSE))),"") -> 3A | AD6: =IFERROR(VLOOKUP(A6,'Flag Football'!A:A,1,FALSE),"") -> Algonquin (Jacobs) | AE6: =IF(AD6="","","1A") -> 1A
A7: Altamont | B7: =IFERROR(VLOOKUP(A7,'Public v Private'!A:G,3,FALSE),"") -> 0 | C7: =IFERROR(VLOOKUP(A7,'Public v Private'!A:G,4,FALSE),"") -> 0 | D7: =IFERROR(VLOOKUP(A7,'Public v Private'!A:G,5,FALSE),"") -> 0 | F7: =IFERROR(INDEX(Fall!$1:$1048576,MATCH(All!$A7,Fall!$A:$A,FALSE),MATCH(All!F$1,Fall!$1:$1,FALSE)),"N/A") -> 228 | G7: =IFERROR(IF(INDEX(Fall!$1:$1048576,MATCH(All!$A7,Fall!$A:$A,FALSE),MATCH(All!G$1,Fall!$1:$1,FALSE))="","",INDEX(Fall!$1:$1048576,MATCH(All!$A7,Fall!$A:$A,FALSE),MATCH(All!G$1,Fall!$1:$1,FALSE))),"") -> 1A | H7: =IFERROR(IF(INDEX(Fall!$1:$1048576,MATCH(All!$A7,Fall!$A:$A,FALSE),MATCH(All!H$1,Fall!$1:$1,FALSE))="","",INDEX(Fall!$1:$1048576,MATCH(All!$A7,Fall!$A:$A,FALSE),MATCH(All!H$1,Fall!$1:$1,FALSE))),"") -> 1A | I7: =IFERROR(IF(INDEX(Fall!$1:$1048576,MATCH(All!$A7,Fall!$A:$A,FALSE),MATCH(All!I$1,Fall!$1:$1,FALSE))="","",INDEX(Fall!$1:$1048576,MATCH(All!$A7,Fall!$A:$A,FALSE),MATCH(All!I$1,Fall!$1:$1,FALSE))),"") -> 1A | J7: =IFERROR(IF(INDEX(Fall!$1:$1048576,MATCH(All!$A7,Fall!$A:$A,FALSE),MATCH(All!J$1,Fall!$1:$1,FALSE))="","",INDEX(Fall!$1:$1048576,MATCH(All!$A7,Fall!$A:$A,FALSE),MATCH(All!J$1,Fall!$1:$1,FALSE))),"") -> 1A | K7: =IFERROR(IF(INDEX(Fall!$1:$1048576,MATCH(All!$A7,Fall!$A:$A,FALSE),MATCH(All!K$1,Fall!$1:$1,FALSE))="","",INDEX(Fall!$1:$1048576,MATCH(All!$A7,Fall!$A:$A,FALSE),MATCH(All!K$1,Fall!$1:$1,FALSE))),"") -> 1A | L7: =IFERROR(IF(INDEX(Fall!$1:$1048576,MATCH(All!$A7,Fall!$A:$A,FALSE),MATCH(All!L$1,Fall!$1:$1,FALSE))="","",INDEX(Fall!$1:$1048576,MATCH(All!$A7,Fall!$A:$A,FALSE),MATCH(All!L$1,Fall!$1:$1,FALSE))),"") | M7: =IFERROR(IF(INDEX(Fall!$1:$1048576,MATCH(All!$A7,Fall!$A:$A,FALSE),MATCH(All!M$1,Fall!$1:$1,FALSE))="","",INDEX(Fall!$1:$1048576,MATCH(All!$A7,Fall!$A:$A,FALSE),MATCH(All!M$1,Fall!$1:$1,FALSE))),"") -> 1A | O7: =IFERROR(IF(INDEX(Winter!$1:$1048576,MATCH(All!$A7,Winter!$A:$A,FALSE),MATCH(All!O$1,Winter!$1:$1,FALSE))="","",INDEX(Winter!$1:$1048576,MATCH(All!$A7,Winter!$A:$A,FALSE),MATCH(All!O$1,Winter!$1:$1,FALSE))),"") -> 228 | P7: =IFERROR(IF(INDEX(Winter!$1:$1048576,MATCH(All!$A7,Winter!$A:$A,FALSE),MATCH(All!P$1,Winter!$1:$1,FALSE))="","",INDEX(Winter!$1:$1048576,MATCH(All!$A7,Winter!$A:$A,FALSE),MATCH(All!P$1,Winter!$1:$1,FALSE))),"") -> 1A | Q7: =IFERROR(IF(INDEX(Winter!$1:$1048576,MATCH(All!$A7,Winter!$A:$A,FALSE),MATCH(All!Q$1,Winter!$1:$1,FALSE))="","",INDEX(Winter!$1:$1048576,MATCH(All!$A7,Winter!$A:$A,FALSE),MATCH(All!Q$1,Winter!$1:$1,FALSE))),"") -> 1A | R7: =IFERROR(IF(INDEX(Winter!$1:$1048576,MATCH(All!$A7,Winter!$A:$A,FALSE),MATCH(All!R$1,Winter!$1:$1,FALSE))="","",INDEX(Winter!$1:$1048576,MATCH(All!$A7,Winter!$A:$A,FALSE),MATCH(All!R$1,Winter!$1:$1,FALSE))),"") | S7: =IFERROR(IF(INDEX(Winter!$1:$1048576,MATCH(All!$A7,Winter!$A:$A,FALSE),MATCH(All!S$1,Winter!$1:$1,FALSE))="","",INDEX(Winter!$1:$1048576,MATCH(All!$A7,Winter!$A:$A,FALSE),MATCH(All!S$1,Winter!$1:$1,FALSE))),"") | T7: =IFERROR(IF(INDEX(Winter!$1:$1048576,MATCH(All!$A7,Winter!$A:$A,FALSE),MATCH(All!T$1,Winter!$1:$1,FALSE))="","",INDEX(Winter!$1:$1048576,MATCH(All!$A7,Winter!$A:$A,FALSE),MATCH(All!T$1,Winter!$1:$1,FALSE))),"") -> 1A | U7: =IFERROR(IF(INDEX(Winter!$1:$1048576,MATCH(All!$A7,Winter!$A:$A,FALSE),MATCH(All!U$1,Winter!$1:$1,FALSE))="","",INDEX(Winter!$1:$1048576,MATCH(All!$A7,Winter!$A:$A,FALSE),MATCH(All!U$1,Winter!$1:$1,FALSE))),"") | W7: =IFERROR(IF(INDEX(Spring!$1:$1048576,MATCH(All!$A7,Spring!$A:$A,FALSE),MATCH(All!W$1,Spring!$1:$1,FALSE))="","",INDEX(Spring!$1:$1048576,MATCH(All!$A7,Spring!$A:$A,FALSE),MATCH(All!W$1,Spring!$1:$1,FALSE))),"") -> 228 | X7: =IFERROR(IF(INDEX(Spring!$1:$1048576,MATCH(All!$A7,Spring!$A:$A,FALSE),MATCH(All!X$1,Spring!$1:$1,FALSE))="","",INDEX(Spring!$1:$1048576,MATCH(All!$A7,Spring!$A:$A,FALSE),MATCH(All!X$1,Spring!$1:$1,FALSE))),"") -> 1A | Y7: =IFERROR(IF(INDEX(Spring!$1:$1048576,MATCH(All!$A7,Spring!$A:$A,FALSE),MATCH(All!Y$1,Spring!$1:$1,FALSE))="","",INDEX(Spring!$1:$1048576,MATCH(All!$A7,Spring!$A:$A,FALSE),MATCH(All!Y$1,Spring!$1:$1,FALSE))),"") -> 1A | Z7: =IFERROR(IF(INDEX(Spring!$1:$1048576,MATCH(All!$A7,Spring!$A:$A,FALSE),MATCH(All!Z$1,Spring!$1:$1,FALSE))="","",INDEX(Spring!$1:$1048576,MATCH(All!$A7,Spring!$A:$A,FALSE),MATCH(All!Z$1,Spring!$1:$1,FALSE))),"") | AA7: =IFERROR(IF(INDEX(Spring!$1:$1048576,MATCH(All!$A7,Spring!$A:$A,FALSE),MATCH(All!AA$1,Spring!$1:$1,FALSE))="","",INDEX(Spring!$1:$1048576,MATCH(All!$A7,Spring!$A:$A,FALSE),MATCH(All!AA$1,Spring!$1:$1,FALSE))),"") | AB7: =IFERROR(IF(INDEX(Spring!$1:$1048576,MATCH(All!$A7,Spring!$A:$A,FALSE),MATCH(All!AB$1,Spring!$1:$1,FALSE))="","",INDEX(Spring!$1:$1048576,MATCH(All!$A7,Spring!$A:$A,FALSE),MATCH(All!AB$1,Spring!$1:$1,FALSE))),"") -> 1A | AC7: =IFERROR(IF(INDEX(Spring!$1:$1048576,MATCH(All!$A7,Spring!$A:$A,FALSE),MATCH(All!AC$1,Spring!$1:$1,FALSE))="","",INDEX(Spring!$1:$1048576,MATCH(All!$A7,Spring!$A:$A,FALSE),MATCH(All!AC$1,Spring!$1:$1,FALSE))),"") -> 1A | AD7: =IFERROR(VLOOKUP(A7,'Flag Football'!A:A,1,FALSE),"") | AE7: =IF(AD7="","","1A")
A8: Alton (Marquette) | B8: =IFERROR(VLOOKUP(A8,'Public v Private'!A:G,3,FALSE),"") -> private | C8: =IFERROR(VLOOKUP(A8,'Public v Private'!A:G,4,FALSE),"") -> 7 | D8: =IFERROR(VLOOKUP(A8,'Public v Private'!A:G,5,FALSE),"") -> 19 | F8: =IFERROR(INDEX(Fall!$1:$1048576,MATCH(All!$A8,Fall!$A:$A,FALSE),MATCH(All!F$1,Fall!$1:$1,FALSE)),"N/A") -> 372.00 (613.80) | G8: =IFERROR(IF(INDEX(Fall!$1:$1048576,MATCH(All!$A8,Fall!$A:$A,FALSE),MATCH(All!G$1,Fall!$1:$1,FALSE))="","",INDEX(Fall!$1:$1048576,MATCH(All!$A8,Fall!$A:$A,FALSE),MATCH(All!G$1,Fall!$1:$1,FALSE))),"") -> 2A | H8: =IFERROR(IF(INDEX(Fall!$1:$1048576,MATCH(All!$A8,Fall!$A:$A,FALSE),MATCH(All!H$1,Fall!$1:$1,FALSE))="","",INDEX(Fall!$1:$1048576,MATCH(All!$A8,Fall!$A:$A,FALSE),MATCH(All!H$1,Fall!$1:$1,FALSE))),"") -> 2A | I8: =IFERROR(IF(INDEX(Fall!$1:$1048576,MATCH(All!$A8,Fall!$A:$A,FALSE),MATCH(All!I$1,Fall!$1:$1,FALSE))="","",INDEX(Fall!$1:$1048576,MATCH(All!$A8,Fall!$A:$A,FALSE),MATCH(All!I$1,Fall!$1:$1,FALSE))),"") -> 2A | J8: =IFERROR(IF(INDEX(Fall!$1:$1048576,MATCH(All!$A8,Fall!$A:$A,FALSE),MATCH(All!J$1,Fall!$1:$1,FALSE))="","",INDEX(Fall!$1:$1048576,MATCH(All!$A8,Fall!$A:$A,FALSE),MATCH(All!J$1,Fall!$1:$1,FALSE))),"") -> 1A | K8: =IFERROR(IF(INDEX(Fall!$1:$1048576,MATCH(All!$A8,Fall!$A:$A,FALSE),MATCH(All!K$1,Fall!$1:$1,FALSE))="","",INDEX(Fall!$1:$1048576,MATCH(All!$A8,Fall!$A:$A,FALSE),MATCH(All!K$1,Fall!$1:$1,FALSE))),"") -> 1A | L8: =IFERROR(IF(INDEX(Fall!$1:$1048576,MATCH(All!$A8,Fall!$A:$A,FALSE),MATCH(All!L$1,Fall!$1:$1,FALSE))="","",INDEX(Fall!$1:$1048576,MATCH(All!$A8,Fall!$A:$A,FALSE),MATCH(All!L$1,Fall!$1:$1,FALSE))),"") -> 1A | M8: =IFERROR(IF(INDEX(Fall!$1:$1048576,MATCH(All!$A8,Fall!$A:$A,FALSE),MATCH(All!M$1,Fall!$1:$1,FALSE))="","",INDEX(Fall!$1:$1048576,MATCH(All!$A8,Fall!$A:$A,FALSE),MATCH(All!M$1,Fall!$1:$1,FALSE))),"") -> 2A | O8: =IFERROR(IF(INDEX(Winter!$1:$1048576,MATCH(All!$A8,Winter!$A:$A,FALSE),MATCH(All!O$1,Winter!$1:$1,FALSE))="","",INDEX(Winter!$1:$1048576,MATCH(All!$A8,Winter!$A:$A,FALSE),MATCH(All!O$1,Winter!$1:$1,FALSE))),"") -> 372.00 (613.80) | P8: =IFERROR(IF(INDEX(Winter!$1:$1048576,MATCH(All!$A8,Winter!$A:$A,FALSE),MATCH(All!P$1,Winter!$1:$1,FALSE))="","",INDEX(Winter!$1:$1048576,MATCH(All!$A8,Winter!$A:$A,FALSE),MATCH(All!P$1,Winter!$1:$1,FALSE))),"") -> 2A | Q8: =IFERROR(IF(INDEX(Winter!$1:$1048576,MATCH(All!$A8,Winter!$A:$A,FALSE),MATCH(All!Q$1,Winter!$1:$1,FALSE))="","",INDEX(Winter!$1:$1048576,MATCH(All!$A8,Winter!$A:$A,FALSE),MATCH(All!Q$1,Winter!$1:$1,FALSE))),"") -> 2A | R8: =IFERROR(IF(INDEX(Winter!$1:$1048576,MATCH(All!$A8,Winter!$A:$A,FALSE),MATCH(All!R$1,Winter!$1:$1,FALSE))="","",INDEX(Winter!$1:$1048576,MATCH(All!$A8,Winter!$A:$A,FALSE),MATCH(All!R$1,Winter!$1:$1,FALSE))),"") | S8: =IFERROR(IF(INDEX(Winter!$1:$1048576,MATCH(All!$A8,Winter!$A:$A,FALSE),MATCH(All!S$1,Winter!$1:$1,FALSE))="","",INDEX(Winter!$1:$1048576,MATCH(All!$A8,Winter!$A:$A,FALSE),MATCH(All!S$1,Winter!$1:$1,FALSE))),"") -> 1A | T8: =IFERROR(IF(INDEX(Winter!$1:$1048576,MATCH(All!$A8,Winter!$A:$A,FALSE),MATCH(All!T$1,Winter!$1:$1,FALSE))="","",INDEX(Winter!$1:$1048576,MATCH(All!$A8,Winter!$A:$A,FALSE),MATCH(All!T$1,Winter!$1:$1,FALSE))),"") -> 2A | U8: =IFERROR(IF(INDEX(Winter!$1:$1048576,MATCH(All!$A8,Winter!$A:$A,FALSE),MATCH(All!U$1,Winter!$1:$1,FALSE))="","",INDEX(Winter!$1:$1048576,MATCH(All!$A8,Winter!$A:$A,FALSE),MATCH(All!U$1,Winter!$1:$1,FALSE))),"") | W8: =IFERROR(IF(INDEX(Spring!$1:$1048576,MATCH(All!$A8,Spring!$A:$A,FALSE),MATCH(All!W$1,Spring!$1:$1,FALSE))="","",INDEX(Spring!$1:$1048576,MATCH(All!$A8,Spring!$A:$A,FALSE),MATCH(All!W$1,Spring!$1:$1,FALSE))),"") -> 372.00 (613.80) | X8: =IFERROR(IF(INDEX(Spring!$1:$1048576,MATCH(All!$A8,Spring!$A:$A,FALSE),MATCH(All!X$1,Spring!$1:$1,FALSE))="","",INDEX(Spring!$1:$1048576,MATCH(All!$A8,Spring!$A:$A,FALSE),MATCH(All!X$1,Spring!$1:$1,FALSE))),"") -> 2A | Y8: =IFERROR(IF(INDEX(Spring!$1:$1048576,MATCH(All!$A8,Spring!$A:$A,FALSE),MATCH(All!Y$1,Spring!$1:$1,FALSE))="","",INDEX(Spring!$1:$1048576,MATCH(All!$A8,Spring!$A:$A,FALSE),MATCH(All!Y$1,Spring!$1:$1,FALSE))),"") -> 2A | Z8: =IFERROR(IF(INDEX(Spring!$1:$1048576,MATCH(All!$A8,Spring!$A:$A,FALSE),MATCH(All!Z$1,Spring!$1:$1,FALSE))="","",INDEX(Spring!$1:$1048576,MATCH(All!$A8,Spring!$A:$A,FALSE),MATCH(All!Z$1,Spring!$1:$1,FALSE))),"") -> 1A | AA8: =IFERROR(IF(INDEX(Spring!$1:$1048576,MATCH(All!$A8,Spring!$A:$A,FALSE),MATCH(All!AA$1,Spring!$1:$1,FALSE))="","",INDEX(Spring!$1:$1048576,MATCH(All!$A8,Spring!$A:$A,FALSE),MATCH(All!AA$1,Spring!$1:$1,FALSE))),"") -> 1A | AB8: =IFERROR(IF(INDEX(Spring!$1:$1048576,MATCH(All!$A8,Spring!$A:$A,FALSE),MATCH(All!AB$1,Spring!$1:$1,FALSE))="","",INDEX(Spring!$1:$1048576,MATCH(All!$A8,Spring!$A:$A,FALSE),MATCH(All!AB$1,Spring!$1:$1,FALSE))),"") -> 2A | AC8: =IFERROR(IF(INDEX(Spring!$1:$1048576,MATCH(All!$A8,Spring!$A:$A,FALSE),MATCH(All!AC$1,Spring!$1:$1,FALSE))="","",INDEX(Spring!$1:$1048576,MATCH(All!$A8,Spring!$A:$A,FALSE),MATCH(All!AC$1,Spring!$1:$1,FALSE))),"") -> 2A | AD8: =IFERROR(VLOOKUP(A8,'Flag Football'!A:A,1,FALSE),"") | AE8: =IF(AD8="","","1A")
A9: Alton (Sr.) | B9: =IFERROR(VLOOKUP(A9,'Public v Private'!A:G,3,FALSE),"") -> 0 | C9: =IFERROR(VLOOKUP(A9,'Public v Private'!A:G,4,FALSE),"") -> 0 | D9: =IFERROR(VLOOKUP(A9,'Public v Private'!A:G,5,FALSE),"") -> 0 | F9: =IFERROR(INDEX(Fall!$1:$1048576,MATCH(All!$A9,Fall!$A:$A,FALSE),MATCH(All!F$1,Fall!$1:$1,FALSE)),"N/A") -> 1759 | G9: =IFERROR(IF(INDEX(Fall!$1:$1048576,MATCH(All!$A9,Fall!$A:$A,FALSE),MATCH(All!G$1,Fall!$1:$1,FALSE))="","",INDEX(Fall!$1:$1048576,MATCH(All!$A9,Fall!$A:$A,FALSE),MATCH(All!G$1,Fall!$1:$1,FALSE))),"") -> 3A | H9: =IFERROR(IF(INDEX(Fall!$1:$1048576,MATCH(All!$A9,Fall!$A:$A,FALSE),MATCH(All!H$1,Fall!$1:$1,FALSE))="","",INDEX(Fall!$1:$1048576,MATCH(All!$A9,Fall!$A:$A,FALSE),MATCH(All!H$1,Fall!$1:$1,FALSE))),"") -> 3A | I9: =IFERROR(IF(INDEX(Fall!$1:$1048576,MATCH(All!$A9,Fall!$A:$A,FALSE),MATCH(All!I$1,Fall!$1:$1,FALSE))="","",INDEX(Fall!$1:$1048576,MATCH(All!$A9,Fall!$A:$A,FALSE),MATCH(All!I$1,Fall!$1:$1,FALSE))),"") -> 3A | J9: =IFERROR(IF(INDEX(Fall!$1:$1048576,MATCH(All!$A9,Fall!$A:$A,FALSE),MATCH(All!J$1,Fall!$1:$1,FALSE))="","",INDEX(Fall!$1:$1048576,MATCH(All!$A9,Fall!$A:$A,FALSE),MATCH(All!J$1,Fall!$1:$1,FALSE))),"") | K9: =IFERROR(IF(INDEX(Fall!$1:$1048576,MATCH(All!$A9,Fall!$A:$A,FALSE),MATCH(All!K$1,Fall!$1:$1,FALSE))="","",INDEX(Fall!$1:$1048576,MATCH(All!$A9,Fall!$A:$A,FALSE),MATCH(All!K$1,Fall!$1:$1,FALSE))),"") -> 3A | L9: =IFERROR(IF(INDEX(Fall!$1:$1048576,MATCH(All!$A9,Fall!$A:$A,FALSE),MATCH(All!L$1,Fall!$1:$1,FALSE))="","",INDEX(Fall!$1:$1048576,MATCH(All!$A9,Fall!$A:$A,FALSE),MATCH(All!L$1,Fall!$1:$1,FALSE))),"") -> 2A | M9: =IFERROR(IF(INDEX(Fall!$1:$1048576,MATCH(All!$A9,Fall!$A:$A,FALSE),MATCH(All!M$1,Fall!$1:$1,FALSE))="","",INDEX(Fall!$1:$1048576,MATCH(All!$A9,Fall!$A:$A,FALSE),MATCH(All!M$1,Fall!$1:$1,FALSE))),"") -> 4A | O9: =IFERROR(IF(INDEX(Winter!$1:$1048576,MATCH(All!$A9,Winter!$A:$A,FALSE),MATCH(All!O$1,Winter!$1:$1,FALSE))="","",INDEX(Winter!$1:$1048576,MATCH(All!$A9,Winter!$A:$A,FALSE),MATCH(All!O$1,Winter!$1:$1,FALSE))),"") -> 1759 | P9: =IFERROR(IF(INDEX(Winter!$1:$1048576,MATCH(All!$A9,Winter!$A:$A,FALSE),MATCH(All!P$1,Winter!$1:$1,FALSE))="","",INDEX(Winter!$1:$1048576,MATCH(All!$A9,Winter!$A:$A,FALSE),MATCH(All!P$1,Winter!$1:$1,FALSE))),"") -> 4A | Q9: =IFERROR(IF(INDEX(Winter!$1:$1048576,MATCH(All!$A9,Winter!$A:$A,FALSE),MATCH(All!Q$1,Winter!$1:$1,FALSE))="","",INDEX(Winter!$1:$1048576,MATCH(All!$A9,Winter!$A:$A,FALSE),MATCH(All!Q$1,Winter!$1:$1,FALSE))),"") -> 4A | R9: =IFERROR(IF(INDEX(Winter!$1:$1048576,MATCH(All!$A9,Winter!$A:$A,FALSE),MATCH(All!R$1,Winter!$1:$1,FALSE))="","",INDEX(Winter!$1:$1048576,MATCH(All!$A9,Winter!$A:$A,FALSE),MATCH(All!R$1,Winter!$1:$1,FALSE))),"") -> C | S9: =IFERROR(IF(INDEX(Winter!$1:$1048576,MATCH(All!$A9,Winter!$A:$A,FALSE),MATCH(All!S$1,Winter!$1:$1,FALSE))="","",INDEX(Winter!$1:$1048576,MATCH(All!$A9,Winter!$A:$A,FALSE),MATCH(All!S$1,Winter!$1:$1,FALSE))),"") -> 2A | T9: =IFERROR(IF(INDEX(Winter!$1:$1048576,MATCH(All!$A9,Winter!$A:$A,FALSE),MATCH(All!T$1,Winter!$1:$1,FALSE))="","",INDEX(Winter!$1:$1048576,MATCH(All!$A9,Winter!$A:$A,FALSE),MATCH(All!T$1,Winter!$1:$1,FALSE))),"") -> 2A | U9: =IFERROR(IF(INDEX(Winter!$1:$1048576,MATCH(All!$A9,Winter!$A:$A,FALSE),MATCH(All!U$1,Winter!$1:$1,FALSE))="","",INDEX(Winter!$1:$1048576,MATCH(All!$A9,Winter!$A:$A,FALSE),MATCH(All!U$1,Winter!$1:$1,FALSE))),"") -> 3A | W9: =IFERROR(IF(INDEX(Spring!$1:$1048576,MATCH(All!$A9,Spring!$A:$A,FALSE),MATCH(All!W$1,Spring!$1:$1,FALSE))="","",INDEX(Spring!$1:$1048576,MATCH(All!$A9,Spring!$A:$A,FALSE),MATCH(All!W$1,Spring!$1:$1,FALSE))),"") -> 1759 | X9: =IFERROR(IF(INDEX(Spring!$1:$1048576,MATCH(All!$A9,Spring!$A:$A,FALSE),MATCH(All!X$1,Spring!$1:$1,FALSE))="","",INDEX(Spring!$1:$1048576,MATCH(All!$A9,Spring!$A:$A,FALSE),MATCH(All!X$1,Spring!$1:$1,FALSE))),"") -> 4A | Y9: =IFERROR(IF(INDEX(Spring!$1:$1048576,MATCH(All!$A9,Spring!$A:$A,FALSE),MATCH(All!Y$1,Spring!$1:$1,FALSE))="","",INDEX(Spring!$1:$1048576,MATCH(All!$A9,Spring!$A:$A,FALSE),MATCH(All!Y$1,Spring!$1:$1,FALSE))),"") -> 4A | Z9: =IFERROR(IF(INDEX(Spring!$1:$1048576,MATCH(All!$A9,Spring!$A:$A,FALSE),MATCH(All!Z$1,Spring!$1:$1,FALSE))="","",INDEX(Spring!$1:$1048576,MATCH(All!$A9,Spring!$A:$A,FALSE),MATCH(All!Z$1,Spring!$1:$1,FALSE))),"") -> 2A | AA9: =IFERROR(IF(INDEX(Spring!$1:$1048576,MATCH(All!$A9,Spring!$A:$A,FALSE),MATCH(All!AA$1,Spring!$1:$1,FALSE))="","",INDEX(Spring!$1:$1048576,MATCH(All!$A9,Spring!$A:$A,FALSE),MATCH(All!AA$1,Spring!$1:$1,FALSE))),"") -> 2A | AB9: =IFERROR(IF(INDEX(Spring!$1:$1048576,MATCH(All!$A9,Spring!$A:$A,FALSE),MATCH(All!AB$1,Spring!$1:$1,FALSE))="","",INDEX(Spring!$1:$1048576,MATCH(All!$A9,Spring!$A:$A,FALSE),MATCH(All!AB$1,Spring!$1:$1,FALSE))),"") -> 3A | AC9: =IFERROR(IF(INDEX(Spring!$1:$1048576,MATCH(All!$A9,Spring!$A:$A,FALSE),MATCH(All!AC$1,Spring!$1:$1,FALSE))="","",INDEX(Spring!$1:$1048576,MATCH(All!$A9,Spring!$A:$A,FALSE),MATCH(All!AC$1,Spring!$1:$1,FALSE))),"") -> 3A | AD9: =IFERROR(VLOOKUP(A9,'Flag Football'!A:A,1,FALSE),"") | AE9: =IF(AD9="","","1A")
A10: Amboy | B10: =IFERROR(VLOOKUP(A10,'Public v Private'!A:G,3,FALSE),"") -> 0 | C10: =IFERROR(VLOOKUP(A10,'Public v Private'!A:G,4,FALSE),"") -> 0 | D10: =IFERROR(VLOOKUP(A10,'Public v Private'!A:G,5,FALSE),"") -> 0 | F10: =IFERROR(INDEX(Fall!$1:$1048576,MATCH(All!$A10,Fall!$A:$A,FALSE),MATCH(All!F$1,Fall!$1:$1,FALSE)),"N/A") -> 222 | G10: =IFERROR(IF(INDEX(Fall!$1:$1048576,MATCH(All!$A10,Fall!$A:$A,FALSE),MATCH(All!G$1,Fall!$1:$1,FALSE))="","",INDEX(Fall!$1:$1048576,MATCH(All!$A10,Fall!$A:$A,FALSE),MATCH(All!G$1,Fall!$1:$1,FALSE))),"") -> 1A | H10: =IFERROR(IF(INDEX(Fall!$1:$1048576,MATCH(All!$A10,Fall!$A:$A,FALSE),MATCH(All!H$1,Fall!$1:$1,FALSE))="","",INDEX(Fall!$1:$1048576,MATCH(All!$A10,Fall!$A:$A,FALSE),MATCH(All!H$1,Fall!$1:$1,FALSE))),"") -> 1A | I10: =IFERROR(IF(INDEX(Fall!$1:$1048576,MATCH(All!$A10,Fall!$A:$A,FALSE),MATCH(All!I$1,Fall!$1:$1,FALSE))="","",INDEX(Fall!$1:$1048576,MATCH(All!$A10,Fall!$A:$A,FALSE),MATCH(All!I$1,Fall!$1:$1,FALSE))),"") -> 1A | J10: =IFERROR(IF(INDEX(Fall!$1:$1048576,MATCH(All!$A10,Fall!$A:$A,FALSE),MATCH(All!J$1,Fall!$1:$1,FALSE))="","",INDEX(Fall!$1:$1048576,MATCH(All!$A10,Fall!$A:$A,FALSE),MATCH(All!J$1,Fall!$1:$1,FALSE))),"") | K10: =IFERROR(IF(INDEX(Fall!$1:$1048576,MATCH(All!$A10,Fall!$A:$A,FALSE),MATCH(All!K$1,Fall!$1:$1,FALSE))="","",INDEX(Fall!$1:$1048576,MATCH(All!$A10,Fall!$A:$A,FALSE),MATCH(All!K$1,Fall!$1:$1,FALSE))),"") | L10: =IFERROR(IF(INDEX(Fall!$1:$1048576,MATCH(All!$A10,Fall!$A:$A,FALSE),MATCH(All!L$1,Fall!$1:$1,FALSE))="","",INDEX(Fall!$1:$1048576,MATCH(All!$A10,Fall!$A:$A,FALSE),MATCH(All!L$1,Fall!$1:$1,FALSE))),"") | M10: =IFERROR(IF(INDEX(Fall!$1:$1048576,MATCH(All!$A10,Fall!$A:$A,FALSE),MATCH(All!M$1,Fall!$1:$1,FALSE))="","",INDEX(Fall!$1:$1048576,MATCH(All!$A10,Fall!$A:$A,FALSE),MATCH(All!M$1,Fall!$1:$1,FALSE))),"") -> 1A | O10: =IFERROR(IF(INDEX(Winter!$1:$1048576,MATCH(All!$A10,Winter!$A:$A,FALSE),MATCH(All!O$1,Winter!$1:$1,FALSE))="","",INDEX(Winter!$1:$1048576,MATCH(All!$A10,Winter!$A:$A,FALSE),MATCH(All!O$1,Winter!$1:$1,FALSE))),"") -> 222 | P10: =IFERROR(IF(INDEX(Winter!$1:$1048576,MATCH(All!$A10,Winter!$A:$A,FALSE),MATCH(All!P$1,Winter!$1:$1,FALSE))="","",INDEX(Winter!$1:$1048576,MATCH(All!$A10,Winter!$A:$A,FALSE),MATCH(All!P$1,Winter!$1:$1,FALSE))),"") -> 1A | Q10: =IFERROR(IF(INDEX(Winter!$1:$1048576,MATCH(All!$A10,Winter!$A:$A,FALSE),MATCH(All!Q$1,Winter!$1:$1,FALSE))="","",INDEX(Winter!$1:$1048576,MATCH(All!$A10,Winter!$A:$A,FALSE),MATCH(All!Q$1,Winter!$1:$1,FALSE))),"") -> 1A | R10: =IFERROR(IF(INDEX(Winter!$1:$1048576,MATCH(All!$A10,Winter!$A:$A,FALSE),MATCH(All!R$1,Winter!$1:$1,FALSE))="","",INDEX(Winter!$1:$1048576,MATCH(All!$A10,Winter!$A:$A,FALSE),MATCH(All!R$1,Winter!$1:$1,FALSE))),"") | S10: =IFERROR(IF(INDEX(Winter!$1:$1048576,MATCH(All!$A10,Winter!$A:$A,FALSE),MATCH(All!S$1,Winter!$1:$1,FALSE))="","",INDEX(Winter!$1:$1048576,MATCH(All!$A10,Winter!$A:$A,FALSE),MATCH(All!S$1,Winter!$1:$1,FALSE))),"") | T10: =IFERROR(IF(INDEX(Winter!$1:$1048576,MATCH(All!$A10,Winter!$A:$A,FALSE),MATCH(All!T$1,Winter!$1:$1,FALSE))="","",INDEX(Winter!$1:$1048576,MATCH(All!$A10,Winter!$A:$A,FALSE),MATCH(All!T$1,Winter!$1:$1,FALSE))),"") -> 1A | U10: =IFERROR(IF(INDEX(Winter!$1:$1048576,MATCH(All!$A10,Winter!$A:$A,FALSE),MATCH(All!U$1,Winter!$1:$1,FALSE))="","",INDEX(Winter!$1:$1048576,MATCH(All!$A10,Winter!$A:$A,FALSE),MATCH(All!U$1,Winter!$1:$1,FALSE))),"") -> 1A | W10: =IFERROR(IF(INDEX(Spring!$1:$1048576,MATCH(All!$A10,Spring!$A:$A,FALSE),MATCH(All!W$1,Spring!$1:$1,FALSE))="","",INDEX(Spring!$1:$1048576,MATCH(All!$A10,Spring!$A:$A,FALSE),MATCH(All!W$1,Spring!$1:$1,FALSE))),"") -> 222 | X10: =IFERROR(IF(INDEX(Spring!$1:$1048576,MATCH(All!$A10,Spring!$A:$A,FALSE),MATCH(All!X$1,Spring!$1:$1,FALSE))="","",INDEX(Spring!$1:$1048576,MATCH(All!$A10,Spring!$A:$A,FALSE),MATCH(All!X$1,Spring!$1:$1,FALSE))),"") -> 1A | Y10: =IFERROR(IF(INDEX(Spring!$1:$1048576,MATCH(All!$A10,Spring!$A:$A,FALSE),MATCH(All!Y$1,Spring!$1:$1,FALSE))="","",INDEX(Spring!$1:$1048576,MATCH(All!$A10,Spring!$A:$A,FALSE),MATCH(All!Y$1,Spring!$1:$1,FALSE))),"") -> 1A | Z10: =IFERROR(IF(INDEX(Spring!$1:$1048576,MATCH(All!$A10,Spring!$A:$A,FALSE),MATCH(All!Z$1,Spring!$1:$1,FALSE))="","",INDEX(Spring!$1:$1048576,MATCH(All!$A10,Spring!$A:$A,FALSE),MATCH(All!Z$1,Spring!$1:$1,FALSE))),"") | AA10: =IFERROR(IF(INDEX(Spring!$1:$1048576,MATCH(All!$A10,Spring!$A:$A,FALSE),MATCH(All!AA$1,Spring!$1:$1,FALSE))="","",INDEX(Spring!$1:$1048576,MATCH(All!$A10,Spring!$A:$A,FALSE),MATCH(All!AA$1,Spring!$1:$1,FALSE))),"") | AB10: =IFERROR(IF(INDEX(Spring!$1:$1048576,MATCH(All!$A10,Spring!$A:$A,FALSE),MATCH(All!AB$1,Spring!$1:$1,FALSE))="","",INDEX(Spring!$1:$1048576,MATCH(All!$A10,Spring!$A:$A,FALSE),MATCH(All!AB$1,Spring!$1:$1,FALSE))),"") -> 1A | AC10: =IFERROR(IF(INDEX(Spring!$1:$1048576,MATCH(All!$A10,Spring!$A:$A,FALSE),MATCH(All!AC$1,Spring!$1:$1,FALSE))="","",INDEX(Spring!$1:$1048576,MATCH(All!$A10,Spring!$A:$A,FALSE),MATCH(All!AC$1,Spring!$1:$1,FALSE))),"") -> 1A | AD10: =IFERROR(VLOOKUP(A10,'Flag Football'!A:A,1,FALSE),"") | AE10: =IF(AD10="","","1A")
A11: Anna (A.-Jonesboro) | B11: =IFERROR(VLOOKUP(A11,'Public v Private'!A:G,3,FALSE),"") -> 0 | C11: =IFERROR(VLOOKUP(A11,'Public v Private'!A:G,4,FALSE),"") -> 0 | D11: =IFERROR(VLOOKUP(A11,'Public v Private'!A:G,5,FALSE),"") -> 0 | F11: =IFERROR(INDEX(Fall!$1:$1048576,MATCH(All!$A11,Fall!$A:$A,FALSE),MATCH(All!F$1,Fall!$1:$1,FALSE)),"N/A") -> 453 | G11: =IFERROR(IF(INDEX(Fall!$1:$1048576,MATCH(All!$A11,Fall!$A:$A,FALSE),MATCH(All!G$1,Fall!$1:$1,FALSE))="","",INDEX(Fall!$1:$1048576,MATCH(All!$A11,Fall!$A:$A,FALSE),MATCH(All!G$1,Fall!$1:$1,FALSE))),"") -> 1A | H11: =IFERROR(IF(INDEX(Fall!$1:$1048576,MATCH(All!$A11,Fall!$A:$A,FALSE),MATCH(All!H$1,Fall!$1:$1,FALSE))="","",INDEX(Fall!$1:$1048576,MATCH(All!$A11,Fall!$A:$A,FALSE),MATCH(All!H$1,Fall!$1:$1,FALSE))),"") -> 1A | I11: =IFERROR(IF(INDEX(Fall!$1:$1048576,MATCH(All!$A11,Fall!$A:$A,FALSE),MATCH(All!I$1,Fall!$1:$1,FALSE))="","",INDEX(Fall!$1:$1048576,MATCH(All!$A11,Fall!$A:$A,FALSE),MATCH(All!I$1,Fall!$1:$1,FALSE))),"") -> 1A | J11: =IFERROR(IF(INDEX(Fall!$1:$1048576,MATCH(All!$A11,Fall!$A:$A,FALSE),MATCH(All!J$1,Fall!$1:$1,FALSE))="","",INDEX(Fall!$1:$1048576,MATCH(All!$A11,Fall!$A:$A,FALSE),MATCH(All!J$1,Fall!$1:$1,FALSE))),"") -> 1A | K11: =IFERROR(IF(INDEX(Fall!$1:$1048576,MATCH(All!$A11,Fall!$A:$A,FALSE),MATCH(All!K$1,Fall!$1:$1,FALSE))="","",INDEX(Fall!$1:$1048576,MATCH(All!$A11,Fall!$A:$A,FALSE),MATCH(All!K$1,Fall!$1:$1,FALSE))),"") -> 1A | L11: =IFERROR(IF(INDEX(Fall!$1:$1048576,MATCH(All!$A11,Fall!$A:$A,FALSE),MATCH(All!L$1,Fall!$1:$1,FALSE))="","",INDEX(Fall!$1:$1048576,MATCH(All!$A11,Fall!$A:$A,FALSE),MATCH(All!L$1,Fall!$1:$1,FALSE))),"") | M11: =IFERROR(IF(INDEX(Fall!$1:$1048576,MATCH(All!$A11,Fall!$A:$A,FALSE),MATCH(All!M$1,Fall!$1:$1,FALSE))="","",INDEX(Fall!$1:$1048576,MATCH(All!$A11,Fall!$A:$A,FALSE),MATCH(All!M$1,Fall!$1:$1,FALSE))),"") -> 2A | O11: =IFERROR(IF(INDEX(Winter!$1:$1048576,MATCH(All!$A11,Winter!$A:$A,FALSE),MATCH(All!O$1,Winter!$1:$1,FALSE))="","",INDEX(Winter!$1:$1048576,MATCH(All!$A11,Winter!$A:$A,FALSE),MATCH(All!O$1,Winter!$1:$1,FALSE))),"") -> 453 | P11: =IFERROR(IF(INDEX(Winter!$1:$1048576,MATCH(All!$A11,Winter!$A:$A,FALSE),MATCH(All!P$1,Winter!$1:$1,FALSE))="","",INDEX(Winter!$1:$1048576,MATCH(All!$A11,Winter!$A:$A,FALSE),MATCH(All!P$1,Winter!$1:$1,FALSE))),"") -> 2A | Q11: =IFERROR(IF(INDEX(Winter!$1:$1048576,MATCH(All!$A11,Winter!$A:$A,FALSE),MATCH(All!Q$1,Winter!$1:$1,FALSE))="","",INDEX(Winter!$1:$1048576,MATCH(All!$A11,Winter!$A:$A,FALSE),MATCH(All!Q$1,Winter!$1:$1,FALSE))),"") -> 2A | R11: =IFERROR(IF(INDEX(Winter!$1:$1048576,MATCH(All!$A11,Winter!$A:$A,FALSE),MATCH(All!R$1,Winter!$1:$1,FALSE))="","",INDEX(Winter!$1:$1048576,MATCH(All!$A11,Winter!$A:$A,FALSE),MATCH(All!R$1,Winter!$1:$1,FALSE))),"") | S11: =IFERROR(IF(INDEX(Winter!$1:$1048576,MATCH(All!$A11,Winter!$A:$A,FALSE),MATCH(All!S$1,Winter!$1:$1,FALSE))="","",INDEX(Winter!$1:$1048576,MATCH(All!$A11,Winter!$A:$A,FALSE),MATCH(All!S$1,Winter!$1:$1,FALSE))),"") | T11: =IFERROR(IF(INDEX(Winter!$1:$1048576,MATCH(All!$A11,Winter!$A:$A,FALSE),MATCH(All!T$1,Winter!$1:$1,FALSE))="","",INDEX(Winter!$1:$1048576,MATCH(All!$A11,Winter!$A:$A,FALSE),MATCH(All!T$1,Winter!$1:$1,FALSE))),"") -> 2A | U11: =IFERROR(IF(INDEX(Winter!$1:$1048576,MATCH(All!$A11,Winter!$A:$A,FALSE),MATCH(All!U$1,Winter!$1:$1,FALSE))="","",INDEX(Winter!$1:$1048576,MATCH(All!$A11,Winter!$A:$A,FALSE),MATCH(All!U$1,Winter!$1:$1,FALSE))),"") -> 1A | W11: =IFERROR(IF(INDEX(Spring!$1:$1048576,MATCH(All!$A11,Spring!$A:$A,FALSE),MATCH(All!W$1,Spring!$1:$1,FALSE))="","",INDEX(Spring!$1:$1048576,MATCH(All!$A11,Spring!$A:$A,FALSE),MATCH(All!W$1,Spring!$1:$1,FALSE))),"") -> 453 | X11: =IFERROR(IF(INDEX(Spring!$1:$1048576,MATCH(All!$A11,Spring!$A:$A,FALSE),MATCH(All!X$1,Spring!$1:$1,FALSE))="","",INDEX(Spring!$1:$1048576,MATCH(All!$A11,Spring!$A:$A,FALSE),MATCH(All!X$1,Spring!$1:$1,FALSE))),"") -> 2A | Y11: =IFERROR(IF(INDEX(Spring!$1:$1048576,MATCH(All!$A11,Spring!$A:$A,FALSE),MATCH(All!Y$1,Spring!$1:$1,FALSE))="","",INDEX(Spring!$1:$1048576,MATCH(All!$A11,Spring!$A:$A,FALSE),MATCH(All!Y$1,Spring!$1:$1,FALSE))),"") -> 2A | Z11: =IFERROR(IF(INDEX(Spring!$1:$1048576,MATCH(All!$A11,Spring!$A:$A,FALSE),MATCH(All!Z$1,Spring!$1:$1,FALSE))="","",INDEX(Spring!$1:$1048576,MATCH(All!$A11,Spring!$A:$A,FALSE),MATCH(All!Z$1,Spring!$1:$1,FALSE))),"") -> 1A | AA11: =IFERROR(IF(INDEX(Spring!$1:$1048576,MATCH(All!$A11,Spring!$A:$A,FALSE),MATCH(All!AA$1,Spring!$1:$1,FALSE))="","",INDEX(Spring!$1:$1048576,MATCH(All!$A11,Spring!$A:$A,FALSE),MATCH(All!AA$1,Spring!$1:$1,FALSE))),"") | AB11: =IFERROR(IF(INDEX(Spring!$1:$1048576,MATCH(All!$A11,Spring!$A:$A,FALSE),MATCH(All!AB$1,Spring!$1:$1,FALSE))="","",INDEX(Spring!$1:$1048576,MATCH(All!$A11,Spring!$A:$A,FALSE),MATCH(All!AB$1,Spring!$1:$1,FALSE))),"") -> 2A | AC11: =IFERROR(IF(INDEX(Spring!$1:$1048576,MATCH(All!$A11,Spring!$A:$A,FALSE),MATCH(All!AC$1,Spring!$1:$1,FALSE))="","",INDEX(Spring!$1:$1048576,MATCH(All!$A11,Spring!$A:$A,FALSE),MATCH(All!AC$1,Spring!$1:$1,FALSE))),"") -> 2A | AD11: =IFERROR(VLOOKUP(A11,'Flag Football'!A:A,1,FALSE),"") | AE11: =IF(AD11="","","1A")
A12: Annawan | B12: =IFERROR(VLOOKUP(A12,'Public v Private'!A:G,3,FALSE),"") -> 0 | C12: =IFERROR(VLOOKUP(A12,'Public v Private'!A:G,4,FALSE),"") -> 0 | D12: =IFERROR(VLOOKUP(A12,'Public v Private'!A:G,5,FALSE),"") -> 0 | F12: =IFERROR(INDEX(Fall!$1:$1048576,MATCH(All!$A12,Fall!$A:$A,FALSE),MATCH(All!F$1,Fall!$1:$1,FALSE)),"N/A") -> 94 | G12: =IFERROR(IF(INDEX(Fall!$1:$1048576,MATCH(All!$A12,Fall!$A:$A,FALSE),MATCH(All!G$1,Fall!$1:$1,FALSE))="","",INDEX(Fall!$1:$1048576,MATCH(All!$A12,Fall!$A:$A,FALSE),MATCH(All!G$1,Fall!$1:$1,FALSE))),"") | H12: =IFERROR(IF(INDEX(Fall!$1:$1048576,MATCH(All!$A12,Fall!$A:$A,FALSE),MATCH(All!H$1,Fall!$1:$1,FALSE))="","",INDEX(Fall!$1:$1048576,MATCH(All!$A12,Fall!$A:$A,FALSE),MATCH(All!H$1,Fall!$1:$1,FALSE))),"") | I12: =IFERROR(IF(INDEX(Fall!$1:$1048576,MATCH(All!$A12,Fall!$A:$A,FALSE),MATCH(All!I$1,Fall!$1:$1,FALSE))="","",INDEX(Fall!$1:$1048576,MATCH(All!$A12,Fall!$A:$A,FALSE),MATCH(All!I$1,Fall!$1:$1,FALSE))),"") | J12: =IFERROR(IF(INDEX(Fall!$1:$1048576,MATCH(All!$A12,Fall!$A:$A,FALSE),MATCH(All!J$1,Fall!$1:$1,FALSE))="","",INDEX(Fall!$1:$1048576,MATCH(All!$A12,Fall!$A:$A,FALSE),MATCH(All!J$1,Fall!$1:$1,FALSE))),"") | K12: =IFERROR(IF(INDEX(Fall!$1:$1048576,MATCH(All!$A12,Fall!$A:$A,FALSE),MATCH(All!K$1,Fall!$1:$1,FALSE))="","",INDEX(Fall!$1:$1048576,MATCH(All!$A12,Fall!$A:$A,FALSE),MATCH(All!K$1,Fall!$1:$1,FALSE))),"") | L12: =IFERROR(IF(INDEX(Fall!$1:$1048576,MATCH(All!$A12,Fall!$A:$A,FALSE),MATCH(All!L$1,Fall!$1:$1,FALSE))="","",INDEX(Fall!$1:$1048576,MATCH(All!$A12,Fall!$A:$A,FALSE),MATCH(All!L$1,Fall!$1:$1,FALSE))),"") | M12: =IFERROR(IF(INDEX(Fall!$1:$1048576,MATCH(All!$A12,Fall!$A:$A,FALSE),MATCH(All!M$1,Fall!$1:$1,FALSE))="","",INDEX(Fall!$1:$1048576,MATCH(All!$A12,Fall!$A:$A,FALSE),MATCH(All!M$1,Fall!$1:$1,FALSE))),"") -> 1A | O12: =IFERROR(IF(INDEX(Winter!$1:$1048576,MATCH(All!$A12,Winter!$A:$A,FALSE),MATCH(All!O$1,Winter!$1:$1,FALSE))="","",INDEX(Winter!$1:$1048576,MATCH(All!$A12,Winter!$A:$A,FALSE),MATCH(All!O$1,Winter!$1:$1,FALSE))),"") -> 94 | P12: =IFERROR(IF(INDEX(Winter!$1:$1048576,MATCH(All!$A12,Winter!$A:$A,FALSE),MATCH(All!P$1,Winter!$1:$1,FALSE))="","",INDEX(Winter!$1:$1048576,MATCH(All!$A12,Winter!$A:$A,FALSE),MATCH(All!P$1,Winter!$1:$1,FALSE))),"") -> 1A | Q12: =IFERROR(IF(INDEX(Winter!$1:$1048576,MATCH(All!$A12,Winter!$A:$A,FALSE),MATCH(All!Q$1,Winter!$1:$1,FALSE))="","",INDEX(Winter!$1:$1048576,MATCH(All!$A12,Winter!$A:$A,FALSE),MATCH(All!Q$1,Winter!$1:$1,FALSE))),"") -> 1A | R12: =IFERROR(IF(INDEX(Winter!$1:$1048576,MATCH(All!$A12,Winter!$A:$A,FALSE),MATCH(All!R$1,Winter!$1:$1,FALSE))="","",INDEX(Winter!$1:$1048576,MATCH(All!$A12,Winter!$A:$A,FALSE),MATCH(All!R$1,Winter!$1:$1,FALSE))),"") | S12: =IFERROR(IF(INDEX(Winter!$1:$1048576,MATCH(All!$A12,Winter!$A:$A,FALSE),MATCH(All!S$1,Winter!$1:$1,FALSE))="","",INDEX(Winter!$1:$1048576,MATCH(All!$A12,Winter!$A:$A,FALSE),MATCH(All!S$1,Winter!$1:$1,FALSE))),"") | T12: =IFERROR(IF(INDEX(Winter!$1:$1048576,MATCH(All!$A12,Winter!$A:$A,FALSE),MATCH(All!T$1,Winter!$1:$1,FALSE))="","",INDEX(Winter!$1:$1048576,MATCH(All!$A12,Winter!$A:$A,FALSE),MATCH(All!T$1,Winter!$1:$1,FALSE))),"") -> 1A | U12: =IFERROR(IF(INDEX(Winter!$1:$1048576,MATCH(All!$A12,Winter!$A:$A,FALSE),MATCH(All!U$1,Winter!$1:$1,FALSE))="","",INDEX(Winter!$1:$1048576,MATCH(All!$A12,Winter!$A:$A,FALSE),MATCH(All!U$1,Winter!$1:$1,FALSE))),"") | W12: =IFERROR(IF(INDEX(Spring!$1:$1048576,MATCH(All!$A12,Spring!$A:$A,FALSE),MATCH(All!W$1,Spring!$1:$1,FALSE))="","",INDEX(Spring!$1:$1048576,MATCH(All!$A12,Spring!$A:$A,FALSE),MATCH(All!W$1,Spring!$1:$1,FALSE))),"") | X12: =IFERROR(IF(INDEX(Spring!$1:$1048576,MATCH(All!$A12,Spring!$A:$A,FALSE),MATCH(All!X$1,Spring!$1:$1,FALSE))="","",INDEX(Spring!$1:$1048576,MATCH(All!$A12,Spring!$A:$A,FALSE),MATCH(All!X$1,Spring!$1:$1,FALSE))),"") | Y12: =IFERROR(IF(INDEX(Spring!$1:$1048576,MATCH(All!$A12,Spring!$A:$A,FALSE),MATCH(All!Y$1,Spring!$1:$1,FALSE))="","",INDEX(Spring!$1:$1048576,MATCH(All!$A12,Spring!$A:$A,FALSE),MATCH(All!Y$1,Spring!$1:$1,FALSE))),"") | Z12: =IFERROR(IF(INDEX(Spring!$1:$1048576,MATCH(All!$A12,Spring!$A:$A,FALSE),MATCH(All!Z$1,Spring!$1:$1,FALSE))="","",INDEX(Spring!$1:$1048576,MATCH(All!$A12,Spring!$A:$A,FALSE),MATCH(All!Z$1,Spring!$1:$1,FALSE))),"") | AA12: =IFERROR(IF(INDEX(Spring!$1:$1048576,MATCH(All!$A12,Spring!$A:$A,FALSE),MATCH(All!AA$1,Spring!$1:$1,FALSE))="","",INDEX(Spring!$1:$1048576,MATCH(All!$A12,Spring!$A:$A,FALSE),MATCH(All!AA$1,Spring!$1:$1,FALSE))),"") | AB12: =IFERROR(IF(INDEX(Spring!$1:$1048576,MATCH(All!$A12,Spring!$A:$A,FALSE),MATCH(All!AB$1,Spring!$1:$1,FALSE))="","",INDEX(Spring!$1:$1048576,MATCH(All!$A12,Spring!$A:$A,FALSE),MATCH(All!AB$1,Spring!$1:$1,FALSE))),"") | AC12: =IFERROR(IF(INDEX(Spring!$1:$1048576,MATCH(All!$A12,Spring!$A:$A,FALSE),MATCH(All!AC$1,Spring!$1:$1,FALSE))="","",INDEX(Spring!$1:$1048576,MATCH(All!$A12,Spring!$A:$A,FALSE),MATCH(All!AC$1,Spring!$1:$1,FALSE))),"") | AD12: =IFERROR(VLOOKUP(A12,'Flag Football'!A:A,1,FALSE),"") | AE12: =IF(AD12="","","1A")
